<?xml version="1.0" ?>
<!-- =================================================================================== -->
<!-- |    This document was autogenerated by xacro from model.xacro                    | -->
<!-- |    EDITING THIS FILE BY HAND IS NOT RECOMMENDED                                 | -->
<!-- =================================================================================== -->
<robot name="tether">
  <!-- Xacro to generate tether SDF -->
  <!-- Note: need to manually find and replace all references to 'revolute'
    with 'universal' in final SDF to get better tether. This also involves adding in a second axis.
    These changes are now all defined in generate_sdf.sh-->
  <link name="element_10">
    <inertial>
      <origin rpy="0 1.5707963267948966 0" xyz="0.11106847017856396 0 0"/>
      <mass value="0.01"/>
      <inertia ixx="4.137068355935517e-05" ixy="0" ixz="0" iyy="4.137068355935517e-05" iyz="0" izz="5.000000000000001e-07"/>
    </inertial>
    <visual>
      <origin rpy="0 1.5707963267948966 0" xyz="0.11106847017856396 0 0"/>
      <geometry>
        <cylinder length="0.22213694035712792" radius="0.01"/>
      </geometry>
    </visual>
    <!-- <collision>
                <origin xyz="${elem_length/2} 0 0" rpy="0 ${pi/2} 0" />
                <geometry>
                    <cylinder length="${elem_length}" radius="${tether_radius}"/> 0.0001
                </geometry>
            </collision> -->
  </link>
  <link name="element_9">
    <inertial>
      <origin rpy="0 1.5707963267948966 0" xyz="0.11106847017856396 0 0"/>
      <mass value="0.01"/>
      <inertia ixx="4.137068355935517e-05" ixy="0" ixz="0" iyy="4.137068355935517e-05" iyz="0" izz="5.000000000000001e-07"/>
    </inertial>
    <visual>
      <origin rpy="0 1.5707963267948966 0" xyz="0.11106847017856396 0 0"/>
      <geometry>
        <cylinder length="0.22213694035712792" radius="0.01"/>
      </geometry>
    </visual>
    <!-- <collision>
                <origin xyz="${elem_length/2} 0 0" rpy="0 ${pi/2} 0" />
                <geometry>
                    <cylinder length="${elem_length}" radius="${tether_radius}"/> 0.0001
                </geometry>
            </collision> -->
  </link>
  <link name="element_8">
    <inertial>
      <origin rpy="0 1.5707963267948966 0" xyz="0.11106847017856396 0 0"/>
      <mass value="0.01"/>
      <inertia ixx="4.137068355935517e-05" ixy="0" ixz="0" iyy="4.137068355935517e-05" iyz="0" izz="5.000000000000001e-07"/>
    </inertial>
    <visual>
      <origin rpy="0 1.5707963267948966 0" xyz="0.11106847017856396 0 0"/>
      <geometry>
        <cylinder length="0.22213694035712792" radius="0.01"/>
      </geometry>
    </visual>
    <!-- <collision>
                <origin xyz="${elem_length/2} 0 0" rpy="0 ${pi/2} 0" />
                <geometry>
                    <cylinder length="${elem_length}" radius="${tether_radius}"/> 0.0001
                </geometry>
            </collision> -->
  </link>
  <link name="element_7">
    <inertial>
      <origin rpy="0 1.5707963267948966 0" xyz="0.11106847017856396 0 0"/>
      <mass value="0.01"/>
      <inertia ixx="4.137068355935517e-05" ixy="0" ixz="0" iyy="4.137068355935517e-05" iyz="0" izz="5.000000000000001e-07"/>
    </inertial>
    <visual>
      <origin rpy="0 1.5707963267948966 0" xyz="0.11106847017856396 0 0"/>
      <geometry>
        <cylinder length="0.22213694035712792" radius="0.01"/>
      </geometry>
    </visual>
    <!-- <collision>
                <origin xyz="${elem_length/2} 0 0" rpy="0 ${pi/2} 0" />
                <geometry>
                    <cylinder length="${elem_length}" radius="${tether_radius}"/> 0.0001
                </geometry>
            </collision> -->
  </link>
  <link name="element_6">
    <inertial>
      <origin rpy="0 1.5707963267948966 0" xyz="0.11106847017856396 0 0"/>
      <mass value="0.01"/>
      <inertia ixx="4.137068355935517e-05" ixy="0" ixz="0" iyy="4.137068355935517e-05" iyz="0" izz="5.000000000000001e-07"/>
    </inertial>
    <visual>
      <origin rpy="0 1.5707963267948966 0" xyz="0.11106847017856396 0 0"/>
      <geometry>
        <cylinder length="0.22213694035712792" radius="0.01"/>
      </geometry>
    </visual>
    <!-- <collision>
                <origin xyz="${elem_length/2} 0 0" rpy="0 ${pi/2} 0" />
                <geometry>
                    <cylinder length="${elem_length}" radius="${tether_radius}"/> 0.0001
                </geometry>
            </collision> -->
  </link>
  <link name="element_5">
    <inertial>
      <origin rpy="0 1.5707963267948966 0" xyz="0.11106847017856396 0 0"/>
      <mass value="0.01"/>
      <inertia ixx="4.137068355935517e-05" ixy="0" ixz="0" iyy="4.137068355935517e-05" iyz="0" izz="5.000000000000001e-07"/>
    </inertial>
    <visual>
      <origin rpy="0 1.5707963267948966 0" xyz="0.11106847017856396 0 0"/>
      <geometry>
        <cylinder length="0.22213694035712792" radius="0.01"/>
      </geometry>
    </visual>
    <!-- <collision>
                <origin xyz="${elem_length/2} 0 0" rpy="0 ${pi/2} 0" />
                <geometry>
                    <cylinder length="${elem_length}" radius="${tether_radius}"/> 0.0001
                </geometry>
            </collision> -->
  </link>
  <link name="element_4">
    <inertial>
      <origin rpy="0 1.5707963267948966 0" xyz="0.11106847017856396 0 0"/>
      <mass value="0.01"/>
      <inertia ixx="4.137068355935517e-05" ixy="0" ixz="0" iyy="4.137068355935517e-05" iyz="0" izz="5.000000000000001e-07"/>
    </inertial>
    <visual>
      <origin rpy="0 1.5707963267948966 0" xyz="0.11106847017856396 0 0"/>
      <geometry>
        <cylinder length="0.22213694035712792" radius="0.01"/>
      </geometry>
    </visual>
    <!-- <collision>
                <origin xyz="${elem_length/2} 0 0" rpy="0 ${pi/2} 0" />
                <geometry>
                    <cylinder length="${elem_length}" radius="${tether_radius}"/> 0.0001
                </geometry>
            </collision> -->
  </link>
  <link name="element_3">
    <inertial>
      <origin rpy="0 1.5707963267948966 0" xyz="0.11106847017856396 0 0"/>
      <mass value="0.01"/>
      <inertia ixx="4.137068355935517e-05" ixy="0" ixz="0" iyy="4.137068355935517e-05" iyz="0" izz="5.000000000000001e-07"/>
    </inertial>
    <visual>
      <origin rpy="0 1.5707963267948966 0" xyz="0.11106847017856396 0 0"/>
      <geometry>
        <cylinder length="0.22213694035712792" radius="0.01"/>
      </geometry>
    </visual>
    <!-- <collision>
                <origin xyz="${elem_length/2} 0 0" rpy="0 ${pi/2} 0" />
                <geometry>
                    <cylinder length="${elem_length}" radius="${tether_radius}"/> 0.0001
                </geometry>
            </collision> -->
  </link>
  <link name="element_2">
    <inertial>
      <origin rpy="0 1.5707963267948966 0" xyz="0.11106847017856396 0 0"/>
      <mass value="0.01"/>
      <inertia ixx="4.137068355935517e-05" ixy="0" ixz="0" iyy="4.137068355935517e-05" iyz="0" izz="5.000000000000001e-07"/>
    </inertial>
    <visual>
      <origin rpy="0 1.5707963267948966 0" xyz="0.11106847017856396 0 0"/>
      <geometry>
        <cylinder length="0.22213694035712792" radius="0.01"/>
      </geometry>
    </visual>
    <!-- <collision>
                <origin xyz="${elem_length/2} 0 0" rpy="0 ${pi/2} 0" />
                <geometry>
                    <cylinder length="${elem_length}" radius="${tether_radius}"/> 0.0001
                </geometry>
            </collision> -->
  </link>
  <link name="element_1">
    <inertial>
      <origin rpy="0 1.5707963267948966 0" xyz="0.11106847017856396 0 0"/>
      <mass value="0.01"/>
      <inertia ixx="4.137068355935517e-05" ixy="0" ixz="0" iyy="4.137068355935517e-05" iyz="0" izz="5.000000000000001e-07"/>
    </inertial>
    <visual>
      <origin rpy="0 1.5707963267948966 0" xyz="0.11106847017856396 0 0"/>
      <geometry>
        <cylinder length="0.22213694035712792" radius="0.01"/>
      </geometry>
    </visual>
    <!-- <collision>
                <origin xyz="${elem_length/2} 0 0" rpy="0 ${pi/2} 0" />
                <geometry>
                    <cylinder length="${elem_length}" radius="${tether_radius}"/> 0.0001
                </geometry>
            </collision> -->
  </link>
  <joint name="joint_1_to_2" type="continuous">
    <axis xyz="0. 1. 0."/>
    <!-- <axis xyz="0. 1. 1."/> -->
    <origin rpy="0 -0.3141592653589793 0" xyz="0.22213694035712792 0 0"/>
    <!-- <xacro:if value="${elem_num  == 1}">
                    <origin xyz="${elem_length_main} 0 0" rpy="0 ${ang_i/2} 0"/>
                </xacro:if>
                <xacro:if value="${elem_num  == num_elements}">
                    <origin xyz="${elem_length_main} 0 0" rpy="0 ${(pi-ang_e)/2} 0"/>
                </xacro:if>
                <xacro:if value="${(elem_num > 1) and (elem_num < num_elements)}">
                    <origin xyz="${elem_length_main} 0 0" rpy="0 ${-ang_e} 0"/>
                </xacro:if> -->
    <parent link="element_1"/>
    <child link="element_2"/>
    <dynamics damping="0.01" friction="0"/>
  </joint>
  <joint name="joint_2_to_3" type="continuous">
    <axis xyz="0. 1. 0."/>
    <!-- <axis xyz="0. 1. 1."/> -->
    <origin rpy="0 -0.3141592653589793 0" xyz="0.22213694035712792 0 0"/>
    <!-- <xacro:if value="${elem_num  == 1}">
                    <origin xyz="${elem_length_main} 0 0" rpy="0 ${ang_i/2} 0"/>
                </xacro:if>
                <xacro:if value="${elem_num  == num_elements}">
                    <origin xyz="${elem_length_main} 0 0" rpy="0 ${(pi-ang_e)/2} 0"/>
                </xacro:if>
                <xacro:if value="${(elem_num > 1) and (elem_num < num_elements)}">
                    <origin xyz="${elem_length_main} 0 0" rpy="0 ${-ang_e} 0"/>
                </xacro:if> -->
    <parent link="element_2"/>
    <child link="element_3"/>
    <dynamics damping="0.01" friction="0"/>
  </joint>
  <joint name="joint_3_to_4" type="continuous">
    <axis xyz="0. 1. 0."/>
    <!-- <axis xyz="0. 1. 1."/> -->
    <origin rpy="0 -0.3141592653589793 0" xyz="0.22213694035712792 0 0"/>
    <!-- <xacro:if value="${elem_num  == 1}">
                    <origin xyz="${elem_length_main} 0 0" rpy="0 ${ang_i/2} 0"/>
                </xacro:if>
                <xacro:if value="${elem_num  == num_elements}">
                    <origin xyz="${elem_length_main} 0 0" rpy="0 ${(pi-ang_e)/2} 0"/>
                </xacro:if>
                <xacro:if value="${(elem_num > 1) and (elem_num < num_elements)}">
                    <origin xyz="${elem_length_main} 0 0" rpy="0 ${-ang_e} 0"/>
                </xacro:if> -->
    <parent link="element_3"/>
    <child link="element_4"/>
    <dynamics damping="0.01" friction="0"/>
  </joint>
  <joint name="joint_4_to_5" type="continuous">
    <axis xyz="0. 1. 0."/>
    <!-- <axis xyz="0. 1. 1."/> -->
    <origin rpy="0 -0.3141592653589793 0" xyz="0.22213694035712792 0 0"/>
    <!-- <xacro:if value="${elem_num  == 1}">
                    <origin xyz="${elem_length_main} 0 0" rpy="0 ${ang_i/2} 0"/>
                </xacro:if>
                <xacro:if value="${elem_num  == num_elements}">
                    <origin xyz="${elem_length_main} 0 0" rpy="0 ${(pi-ang_e)/2} 0"/>
                </xacro:if>
                <xacro:if value="${(elem_num > 1) and (elem_num < num_elements)}">
                    <origin xyz="${elem_length_main} 0 0" rpy="0 ${-ang_e} 0"/>
                </xacro:if> -->
    <parent link="element_4"/>
    <child link="element_5"/>
    <dynamics damping="0.01" friction="0"/>
  </joint>
  <joint name="joint_5_to_6" type="continuous">
    <axis xyz="0. 1. 0."/>
    <!-- <axis xyz="0. 1. 1."/> -->
    <origin rpy="0 -0.3141592653589793 0" xyz="0.22213694035712792 0 0"/>
    <!-- <xacro:if value="${elem_num  == 1}">
                    <origin xyz="${elem_length_main} 0 0" rpy="0 ${ang_i/2} 0"/>
                </xacro:if>
                <xacro:if value="${elem_num  == num_elements}">
                    <origin xyz="${elem_length_main} 0 0" rpy="0 ${(pi-ang_e)/2} 0"/>
                </xacro:if>
                <xacro:if value="${(elem_num > 1) and (elem_num < num_elements)}">
                    <origin xyz="${elem_length_main} 0 0" rpy="0 ${-ang_e} 0"/>
                </xacro:if> -->
    <parent link="element_5"/>
    <child link="element_6"/>
    <dynamics damping="0.01" friction="0"/>
  </joint>
  <joint name="joint_6_to_7" type="continuous">
    <axis xyz="0. 1. 0."/>
    <!-- <axis xyz="0. 1. 1."/> -->
    <origin rpy="0 -0.3141592653589793 0" xyz="0.22213694035712792 0 0"/>
    <!-- <xacro:if value="${elem_num  == 1}">
                    <origin xyz="${elem_length_main} 0 0" rpy="0 ${ang_i/2} 0"/>
                </xacro:if>
                <xacro:if value="${elem_num  == num_elements}">
                    <origin xyz="${elem_length_main} 0 0" rpy="0 ${(pi-ang_e)/2} 0"/>
                </xacro:if>
                <xacro:if value="${(elem_num > 1) and (elem_num < num_elements)}">
                    <origin xyz="${elem_length_main} 0 0" rpy="0 ${-ang_e} 0"/>
                </xacro:if> -->
    <parent link="element_6"/>
    <child link="element_7"/>
    <dynamics damping="0.01" friction="0"/>
  </joint>
  <joint name="joint_7_to_8" type="continuous">
    <axis xyz="0. 1. 0."/>
    <!-- <axis xyz="0. 1. 1."/> -->
    <origin rpy="0 -0.3141592653589793 0" xyz="0.22213694035712792 0 0"/>
    <!-- <xacro:if value="${elem_num  == 1}">
                    <origin xyz="${elem_length_main} 0 0" rpy="0 ${ang_i/2} 0"/>
                </xacro:if>
                <xacro:if value="${elem_num  == num_elements}">
                    <origin xyz="${elem_length_main} 0 0" rpy="0 ${(pi-ang_e)/2} 0"/>
                </xacro:if>
                <xacro:if value="${(elem_num > 1) and (elem_num < num_elements)}">
                    <origin xyz="${elem_length_main} 0 0" rpy="0 ${-ang_e} 0"/>
                </xacro:if> -->
    <parent link="element_7"/>
    <child link="element_8"/>
    <dynamics damping="0.01" friction="0"/>
  </joint>
  <joint name="joint_8_to_9" type="continuous">
    <axis xyz="0. 1. 0."/>
    <!-- <axis xyz="0. 1. 1."/> -->
    <origin rpy="0 -0.3141592653589793 0" xyz="0.22213694035712792 0 0"/>
    <!-- <xacro:if value="${elem_num  == 1}">
                    <origin xyz="${elem_length_main} 0 0" rpy="0 ${ang_i/2} 0"/>
                </xacro:if>
                <xacro:if value="${elem_num  == num_elements}">
                    <origin xyz="${elem_length_main} 0 0" rpy="0 ${(pi-ang_e)/2} 0"/>
                </xacro:if>
                <xacro:if value="${(elem_num > 1) and (elem_num < num_elements)}">
                    <origin xyz="${elem_length_main} 0 0" rpy="0 ${-ang_e} 0"/>
                </xacro:if> -->
    <parent link="element_8"/>
    <child link="element_9"/>
    <dynamics damping="0.01" friction="0"/>
  </joint>
  <joint name="joint_9_to_10" type="continuous">
    <axis xyz="0. 1. 0."/>
    <!-- <axis xyz="0. 1. 1."/> -->
    <origin rpy="0 -0.3141592653589793 0" xyz="0.22213694035712792 0 0"/>
    <!-- <xacro:if value="${elem_num  == 1}">
                    <origin xyz="${elem_length_main} 0 0" rpy="0 ${ang_i/2} 0"/>
                </xacro:if>
                <xacro:if value="${elem_num  == num_elements}">
                    <origin xyz="${elem_length_main} 0 0" rpy="0 ${(pi-ang_e)/2} 0"/>
                </xacro:if>
                <xacro:if value="${(elem_num > 1) and (elem_num < num_elements)}">
                    <origin xyz="${elem_length_main} 0 0" rpy="0 ${-ang_e} 0"/>
                </xacro:if> -->
    <parent link="element_9"/>
    <child link="element_10"/>
    <dynamics damping="0.01" friction="0"/>
  </joint>
  <link name="element_first">
    <inertial>
      <origin rpy="0 1.5707963267948966 0" xyz="5e-05 0 0"/>
      <mass value="0.0001"/>
      <inertia ixx="2.5000833333333336e-09" ixy="0" ixz="0" iyy="2.5000833333333336e-09" iyz="0" izz="5e-09"/>
    </inertial>
    <visual>
      <origin rpy="0 1.5707963267948966 0" xyz="5e-05 0 0"/>
      <geometry>
        <cylinder length="0.0001" radius="0.01"/>
      </geometry>
    </visual>
    <!-- <collision>
                <origin xyz="${elem_length/2} 0 0" rpy="0 ${pi/2} 0" />
                <geometry>
                    <cylinder length="${elem_length}" radius="${tether_radius}"/> 0.0001
                </geometry>
            </collision> -->
  </link>
  <link name="element_last">
    <inertial>
      <origin rpy="0 1.5707963267948966 0" xyz="5e-05 0 0"/>
      <mass value="0.0001"/>
      <inertia ixx="2.5000833333333336e-09" ixy="0" ixz="0" iyy="2.5000833333333336e-09" iyz="0" izz="5e-09"/>
    </inertial>
    <visual>
      <origin rpy="0 1.5707963267948966 0" xyz="5e-05 0 0"/>
      <geometry>
        <cylinder length="0.0001" radius="0.01"/>
      </geometry>
    </visual>
    <!-- <collision>
                <origin xyz="${elem_length/2} 0 0" rpy="0 ${pi/2} 0" />
                <geometry>
                    <cylinder length="${elem_length}" radius="${tether_radius}"/> 0.0001
                </geometry>
            </collision> -->
  </link>
  <joint name="joint_0_to_1" type="continuous">
    <axis xyz="0. 1. 0."/>
    <origin rpy="0 1.413716694115407 0" xyz="0.0001 0 0"/>
    <parent link="element_first"/>
    <child link="element_1"/>
    <dynamics damping="0.01" friction="0"/>
  </joint>
  <joint name="joint_10_to_11" type="continuous">
    <axis xyz="0. 1. 0."/>
    <origin rpy="0 1.413716694115407 0" xyz="0.22213694035712792 0 0"/>
    <parent link="element_10"/>
    <child link="element_last"/>
    <dynamics damping="0.01" friction="0"/>
  </joint>
</robot>
